Workbook

Sheet 新产品
A1: 产品名（实时更新中） | B1: 开测时间 | C1: 是否下架 | D1: 产品归属 | E1: 题材 | F1: 画风 | G1: 发行商 | H1: 公司归属
A2: Endless Zombies | B2: 46035 | D2: Endless Zombies | E2: 丧尸 | F2: 卡通渲染 | G2: Vividiy | H2: =VLOOKUP(G2,公司归属!$B:$C,2,FALSE) -> Vividiy
A3: Escape from Zarkov | B3: 46043 | D3: Escape from Zarkov | E3: 丧尸 | F3: 卡通渲染 | G3: Larks Holding | H3: =VLOOKUP(G3,公司归属!$B:$C,2,FALSE) -> 尼毕鲁
A4: Last Echo | B4: 46041 | D4: Last Echo | E4: 魔幻/神话/吸血鬼/幻想世界 | F4: 卡通渲染 | G4: Glaciers Game | H4: =VLOOKUP(G4,公司归属!$B:$C,2,FALSE) -> 冰川
A5: Lost Waters | B5: 46040 | D5: Lost Waters | E5: 海岛/水世界/木筏 | F5: 写实 | G5: Warrior Cabera | H5: =VLOOKUP(G5,公司归属!$B:$C,2,FALSE) -> 趣加
A6: Titan Rush | B6: 46038 | D6: Titan Rush | E6: 机甲/赛博科幻 | F6: 写实 | G6: RATING GAME | H6: =VLOOKUP(G6,公司归属!$B:$C,2,FALSE) -> 掌趣
A7: Mad ASylum(CBT) | B7: 46022 | D7: Mad ASylum(CBT) | E7: 丧尸 | F7: 卡通渲染 | G7: Etolies Game | H7: =VLOOKUP(G7,公司归属!$B:$C,2,FALSE) -> Rastar 星辉娱乐
A8: Last Light | B8: 45994 | D8: Last Light | E8: 魔幻/神话/吸血鬼/幻想世界 | F8: 卡通渲染 | G8: Dinosaur-Games | H8: =VLOOKUP(G8,公司归属!$B:$C,2,FALSE) -> 冰川
A9: Deepsea Survival | B9: 46031 | C9: 46036 | D9: Deepsea Survival | E9: 海岛/水世界/木筏 | F9: 卡通渲染 | G9: Lunova Game | H9: =VLOOKUP(G9,公司归属!$B:$C,2,FALSE) -> 完美世界
A10: BlitzLoot | B10: 46031 | C10: 46044 | D10: BlitzLoot | E10: 丧尸 | F10: 卡通渲染 | G10: Rhinos | H10: =VLOOKUP(G10,公司归属!$B:$C,2,FALSE) -> 4399 Games
A11: Darkout Survival | B11: 46030 | D11: Darkout Survival | E11: 丧尸 | F11: 卡通渲染 | G11: SkyRise | H11: =VLOOKUP(G11,公司归属!$B:$C,2,FALSE) -> IGG 天盟数码
A12: Z-Fortress | B12: 46030 | D12: Z-Fortress | E12: 丧尸 | F12: 卡通渲染 | G12: Happy Loong Limited | H12: =VLOOKUP(G12,公司归属!$B:$C,2,FALSE) -> 天龙互娱
A13: Sea of Sand | B13: 46030 | D13: Sea of Sand | E13: 海岛/水世界/木筏 | F13: 卡通渲染 | G13: ACT10 Games | H13: =VLOOKUP(G13,公司归属!$B:$C,2,FALSE) -> 上海奥萌尼科技有限公司
A14: Toy Force | B14: 46027 | D14: Toy Force 玩具力量 | E14: 玩具兵人 | F14: 卡通渲染 | G14: StarFortune | H14: =VLOOKUP(G14,公司归属!$B:$C,2,FALSE) -> 星合
A15: Mine Cosmos | B15: 46027 | D15: Mine Cosmos | E15: 丧尸 | F15: 卡通渲染 | G15: Peachcat Online Co., Limited | H15: =VLOOKUP(G15,公司归属!$B:$C,2,FALSE) -> 北京骑士王国/北京狐之空
A16: Dark Shot: Last Stand | B16: 45978 | D16: =VLOOKUP(#REF!,产品归属!$B:$E,4,FALSE) -> #REF! | E16: 丧尸 | F16: 写实 | G16: Triathlon HK | H16: =VLOOKUP(G16,公司归属!$B:$C,2,FALSE) -> 趣加
A17: Lord Defence | B17: 46022 | D17: Lord Defence | E17: 魔幻/神话/吸血鬼/幻想世界 | F17: 卡通渲染 | G17: ZHU HAI WEN JING TECHNOLOGY CO.LTD | H17: =VLOOKUP(G17,公司归属!$B:$C,2,FALSE) -> ZHU HAI WEN JING TECHNOLOGY CO.LTD
A18: Catch & Build: Land of Pals | B18: 45945 | D18: Catch & Build: Land of Pals | E18: 帕鲁/宠物小精灵/宠物进化 | F18: 卡通渲染 | G18: Joy Nice Games | H18: =VLOOKUP(G18,公司归属!$B:$C,2,FALSE) -> 4399 Games
A19: Lost Oasis: Monster War | B19: 46020 | D19: Lost Oasis: Monster War | E19: 帕鲁/宠物小精灵/宠物进化 | F19: 卡通渲染 | G19: PERASPERA GAMES | H19: =VLOOKUP(G19,公司归属!$B:$C,2,FALSE) -> 龙锐
A20: The Last Bastion | B20: 46019 | D20: The Last Bastion | E20: 丧尸 | F20: 卡通渲染 | G20: Miracle Town | H20: =VLOOKUP(G20,公司归属!$B:$C,2,FALSE) -> Miracle Town
A21: Outbreak County | B21: 46017 | D21: =VLOOKUP(#REF!,产品归属!$B:$E,4,FALSE) -> #REF! | E21: 丧尸 | F21: 卡通渲染 | G21: Eric Guillory | H21: =VLOOKUP(G21,公司归属!$B:$C,2,FALSE) -> 趣加
A22: Zombelt Survival | B22: 46017 | C22: 46025 | D22: Zombelt Survival | E22: 丧尸 | F22: 卡通渲染 | G22: silas makokha | H22: =VLOOKUP(G22,公司归属!$B:$C,2,FALSE) -> 点点
A23: Hope War Z | B23: 46015 | D23: Hope War Z | E23: 丧尸 | F23: 写实 | G23: Droupnir Entertainment | H23: =VLOOKUP(G23,公司归属!$B:$C,2,FALSE) -> 三七互娱
A24: Last Asylum: Plague | B24: 45905 | D24: Last Asylum: Plague | E24: 魔幻/神话/吸血鬼/幻想世界 | F24: 卡通渲染 | G24: Clouldwalker | H24: =VLOOKUP(G24,公司归属!$B:$C,2,FALSE) -> 三七互娱
A25: Fire War | B25: 46014 | D25: Fire War | E25: 丧尸 | F25: 卡通渲染 | G25: EVISTA | H25: =VLOOKUP(G25,公司归属!$B:$C,2,FALSE) -> 途游
A26: Apocalypse: New Dawn | B26: 46014 | D26: =VLOOKUP(#REF!,产品归属!$B:$E,4,FALSE) -> #REF! | E26: 荒漠/沙漠/末日废土 | F26: 卡通渲染 | G26: XFire Games | H26: =VLOOKUP(G26,公司归属!$B:$C,2,FALSE) -> 高图
A27: Wildland Survivor | B27: 46014 | D27: =VLOOKUP(#REF!,产品归属!$B:$E,4,FALSE) -> #REF! | E27: 荒漠/沙漠/末日废土 | F27: 写实 | G27: Germer Studio | H27: =VLOOKUP(G27,公司归属!$B:$C,2,FALSE) -> Germer Studio
A28: Yummigo | B28: 45908 | D28: Yummigo | E28: 帕鲁/宠物小精灵/宠物进化 | F28: 卡通渲染 | G28: SkyRise | H28: =VLOOKUP(G28,公司归属!$B:$C,2,FALSE) -> IGG 天盟数码
A29: Within the Dome: Survival | B29: 45931 | D29: =VLOOKUP(#REF!,产品归属!$B:$E,4,FALSE) -> #REF! | E29: 荒漠/沙漠/末日废土 | F29: 卡通渲染 | G29: Skystone Games | H29: =VLOOKUP(G29,公司归属!$B:$C,2,FALSE) -> 沐瞳
A30: Hope War | B30: 46010 | D30: Hope War 希望战争 | E30: 丧尸 | F30: 卡通渲染 | G30: StarFortune | H30: =VLOOKUP(G30,公司归属!$B:$C,2,FALSE) -> 星合
A31: Legion Forge | B31: 46010 | D31: Legion Forge | E31: 魔幻/神话/吸血鬼/幻想世界 | F31: 卡通渲染 | G31: DHGames | H31: =VLOOKUP(G31,公司归属!$B:$C,2,FALSE) -> DHGames 卓杭
A32: Police War | B32: 46010 | D32: Police War | E32: 黑帮 | F32: 卡通渲染 | G32: VoyagerOne | H32: =VLOOKUP(G32,公司归属!$B:$C,2,FALSE) -> 友塔
A33: Last Furry: Survival | B33: 45979 | D33: Last Furry: Survival 狂化启示录 | E33: 动物拟人 | F33: 卡通渲染 | G33: StarUnion | H33: =VLOOKUP(G33,公司归属!$B:$C,2,FALSE) -> 星合
A34: King Fortress | B34: 45995 | D34: King Fortress | E34: 中世纪/多文明 | F34: 写实 | G34: TipTide Games | H34: =VLOOKUP(G34,公司归属!$B:$C,2,FALSE) -> TipTide Games
A35: Last Extraction: Zombie Tide | B35: 46008 | D35: Last Extraction: Zombie Tide 最后的撤离：丧尸潮 | E35: 丧尸 | F35: 写实 | G35: Triathlon HK | H35: =VLOOKUP(G35,公司归属!$B:$C,2,FALSE) -> 趣加
A36: The War | B36: 46006 | D36: The War | E36: 丧尸 | F36: 卡通渲染 | G36: Ark Game | H36: =VLOOKUP(G36,公司归属!$B:$C,2,FALSE) -> 途游
A37: Lost Day: Survival | B37: 46004 | D37: Lost Day: Survival 沦陷日：生存 | E37: 丧尸 | F37: 卡通渲染 | G37: Lucky Star Techonology Limited | H37: =VLOOKUP(G37,公司归属!$B:$C,2,FALSE) -> 智明星通
A38: Frontline Raiders | B38: 46004 | D38: Frontline Raiders 前线突击队 | E38: 丧尸 | F38: 写实 | G38: Moblazer | H38: =VLOOKUP(G38,公司归属!$B:$C,2,FALSE) -> Moblazer
A39: MineZ Survivor: The Apocalypse | B39: 46003 | D39: MineZ Survivor: The Apocalypse | E39: 丧尸 | F39: 卡通渲染 | G39: Mr Blockman Action Games | H39: =VLOOKUP(G39,公司归属!$B:$C,2,FALSE) -> Mr Blockman Action Games
A40: Poker Chess Heroes | B40: 46003 | D40: Poker Chess Heroes | E40: 魔幻/神话/吸血鬼/幻想世界 | F40: 卡通渲染 | G40: PokerVerse | H40: =VLOOKUP(G40,公司归属!$B:$C,2,FALSE) -> PokerVerse
...

Sheet 公司归属
A1: NO. | B1: Unified Publisher Name | C1: 公司归属
A2: 1 | B2: IGG 天盟数码 | C2: IGG 天盟数码
A3: 2 | B3: TOP GAMES | C3: TOP GAMES
A4: 3 | B4: Yotta | C4: 友塔
A5: 4 | B5: FunPlus | C5: 趣加
A6: 5 | B6: Lilith 莉莉丝 | C6: 莉莉丝
A7: 6 | B7: ELEX 智明星通 | C7: 智明星通
A8: 7 | B8: River Game HK | C8: River Game HK
A9: 8 | B9: Camel Games 壳木 | C9: 壳木
A10: 9 | B10: Interesting Game Network | C10: 龙创
A11: 10 | B11: Century Games | C11: 点点
A12: 11 | B12: FirstFun | C12: FirstFun
A13: 12 | B13: Tap4fun (Hong Kong) | C13: 尼毕鲁
... A491: 490 | B491: Madfun | C491: Madfun
B492: Lucky Star Techonology Limited | C492: 智明星通
B493: Moblazer | C493: Moblazer
B494: Fun Games Teknoloji | C494: Fun Games Teknoloji
B495: Com2uS | C495: Com2uS
B496: LuckyLink | C496: 龙腾简合
B497: Mankirk | C497: Mankirk
B498: DHGames | C498: DHGames 卓杭
B499: silas makokha | C499: 点点
B500: Mr Blockman Action Games | C500: Mr Blockman Action Games
B501: ZHU HAI WEN JING TECHNOLOGY CO.LTD | C501: ZHU HAI WEN JING TECHNOLOGY CO.LTD
B502: PokerVerse | C502: PokerVerse
B503: RABII KORCHI | C503: RABII KORCHI
... B528: Heart Survey | C528: 福建山竹啵啵

Sheet 产品归属
A1: NO. | B1: 产品名（实时更新中） | C1: 总表匹配结果 | D1: Unified ID | E1: 产品归属 | F1: 排查结果 | G1: 题材 | H1: 入口玩法/副玩法-1 | I1: 入口玩法/副玩法-2 | J1: 入口玩法/副玩法/展示策略 | K1: 画风 | L1: 发行商 | M1: 公司归属
A2: 1 | B2: انتقام السلاطين | C2: انتقام السلاطين | D2: 56d6407f64235a7413000001 | E2: 苏丹的复仇 انتقام السلاطين | G2: 中世纪/多文明 | H2: 角色养成 | K2: 写实 | L2: ONEMT | M2: 龙腾简合
A3: 2 | B3: ASTROKINGS: Galactic Survival | C3: ASTROKINGS: Galactic Survival | D3: 5b29a9b114ba675ef41f2ed8 | E3: ASTROKINGS: Galactic Survival 太空王国：宇宙生存战 | G3: 航海/海盗 | K3: 写实 | L3: Tilting Point | M3: Tilting Point
A4: 3 | B4: Ace Division | C4: Ace Division | D4: 67625ce14599a501d5174cd1 | E4: Ace Division 王牌部队 | G4: 现代战争 | K4: 写实 | L4: MBC Group | M4: MBC Group
A5: 4 | B5: Ace Division : فرقة النخبة | C5: #N/A | D5: #N/A | E5: Ace Division 王牌部队中东服 | F5: ST无数据 | G5: 现代战争 | K5: 写实 | L5: MBC Group | M5: MBC Group
A6: 5 | B6: Adventure War | C6: Adventure War | D6: 66fa0c5c1d30b813da3954d5 | E6: Adventure War 冒险战争 | G6: 航海/海盗 | H6: 益智解谜 | K6: 卡通渲染 | L6: Lucky Fortune Games | M6: luckyfortunegames
A7: 6 | B7: Age of Apes | C7: Age of Apes | D7: 5de310bf5c6ace5b5d91ae50 | E7: Age of Apes 猿族时代 | G7: 动物拟人 | K7: 卡通渲染 | L7: FunPlus | M7: 趣加
A8: 7 | B8: Age of Dino | C8: #N/A | D8: #N/A | E8: Age of Dino 恐龙时代 | F8: 下架 | G8: 原始人/石器时代/恐龙时代 | K8: 卡通渲染 | L8: Gamephilos Studio | M8: GAMEPHILOS SINGAPORE
A9: 8 | B9: Age of Empires Mobile | C9: Age of Empires Mobile | D9: 65d5c34346b00723e5e77ebd | E9: Age of Empires Mobile 帝国时代移动版 | G9: 中世纪/多文明 | H9: IP展示/蹭IP | K9: 写实 | L9: Tencent | M9: Tencent 腾讯
A10: 9 | B10: Age of Evolution | C10: Age of Evolution | D10: 63996271173d0f77aa1fb21b | E10: Age of Evolution 进化时代 | G10: 文明进化 | K10: 卡通渲染 | L10: 4399 Games | M10: 4399 Games
A11: 10 | B11: Age of Kings: Skyward Battle | C11: Age of Kings: Skyward Battle | D11: 5643d44002ac64581b000002 | E11: Age of Kings: Skyward Battle 王权争霸：天际之战 | G11: 中世纪/多文明 | K11: 写实 | L11: Elex Technology | M11: 智明星通
A12: 11 | B12: Age of Monarchy | C12: Age of Monarchy | D12: 662c0a73b3ae271b107b8835 | E12: Age of Monarchy 君主时代 | G12: 中世纪/多文明 | H12: 模拟经营 | K12: 写实 | L12: ATOMGAMES | M12: ATOMGAMES
A13: 12 | B13: Age of Origins:Tower Defense | C13: Age of Origins:Tower Defense | D13: 5ba1a19def71a76da561ca41 | E13: Age of Origins:Tower Defense 旭日之城 | G13: 丧尸 | K13: 写实 | L13: Atlas Studio | M13: 趣加
A14: 13 | B14: Age of Z | C14: #N/A | D14: #N/A | E14: Age of Origins:Tower Defense 旭日之城 | F14: 改名 | G14: 丧尸 | K14: 写实 | L14: Camel Games | M14: 壳木
A15: 14 | B15: Age of Origins:Tower Defense | C15: Age of Origins:Tower Defense | D15: 5ba1a19def71a76da561ca41 | E15: Age of Origins:Tower Defense 旭日之城 | G15: 丧尸 | K15: 写实 | L15: Camel Games | M15: 壳木
A16: 15 | B16: Age of Warpath: Global Warzone | C16: Age of Warpath: Global Warzone | D16: 6600ce3df7516f24e66be439 | E16: Age of Warpath: Global Warzone 战争时代：全球战区 | G16: 现代战争 | K16: 写实 | L16: Letang Network Technology | M16: 乐堂
A17: 16 | B17: Age of Warring Empire | C17: Age of Warring Empire | D17: 551b8b9dacaabbdf5000001e | E17: Age of Warring Empire 帝国战争 | G17: 中世纪/多文明 | K17: 写实 | L17: Elex Technology | M17: 智明星通
A18: 17 | B18: Airstrike Assault | C18: #N/A | D18: #N/A | E18: Airstrike Assault 空中打击 | F18: ST无数据 | G18: 现代战争 | K18: 写实 | L18: Bravo Games | M18: 趣加
A19: 18 | B19: Ancient Relic | C19: Ancient Relic | D19: 62c7e2911800970513aef782 | E19: Ancient Relic 古代遗迹 | G19: 原始人/石器时代/恐龙时代 | K19: 卡通渲染 | L19: 37 Interactive Entertainment | M19: 三七互娱
A20: 19 | B20: Ant Kingdom: Survival War | C20: #N/A | D20: #N/A | E20: Ant Kingdom: Survival War 蚂蚁王国：幸存者战争 | F20: 下架 | G20: 蚂蚁 | K20: 卡通渲染 | L20: Clouldwalker | M20: 三七互娱
A21: 20 | B21: Ant Legion: For The Swarm | C21: Ant Legion: For The Swarm | D21: 61b1f7b96ffae75bc24b4d78 | E21: Ant Legion: For The Swarm 蚂蚁军团 | G21: 蚂蚁 | H21: 数字门/跑酷 | I21: 角色养成 | K21: 写实 | L21: FunPlus | M21: 趣加
A22: 21 | B22: Ape Avengers | C22: Ape Avengers | D22: 657bbf1514498b12513b4b6c | E22: Ape Avengers 猿族之怒 | G22: 动物拟人 | K22: 卡通渲染 | L22: Tap4Fun | M22: 尼毕鲁
A23: 22 | B23: Ape Chaos | C23: Ape Chaos | D23: 657a855474d0e66f4f2e1aad | E23: Ape Chaos 巨猿战场 | G23: 动物拟人 | H23: IP展示/蹭IP | K23: 写实 | L23: Tap4Fun | M23: 尼毕鲁
A24: 23 | B24: Ape Commandos | C24: Ape Commandos | D24: 6737ad4227e2c12449540d23 | E24: Ape Commandos 猴子冲突 | G24: 动物拟人 | K24: 卡通渲染 | L24: Tap4Fun | M24: 尼毕鲁
A25: 24 | B25: Ape Land | C25: Ape Land | D25: 6776ad3227e2c1ec81612792 | E25: Ape Land 时代之地 | G25: 动物拟人 | K25: 卡通渲染 | L25: Tap4Fun | M25: 尼毕鲁
A26: 25 | B26: Ape TD: Central Defense | C26: Ape TD: Central Defense | D26: 657a9922143f3d466240844b | E26: Ape TD: Central Defense 猿猴塔防：中央防御 | G26: 动物拟人 | K26: 卡通渲染 | L26: Tap4Fun | M26: 尼毕鲁
A27: 26 | B27: Ape TD: Tower Takeover | C27: #N/A | D27: #N/A | E27: Ape TD: Central Defense 猿猴塔防：中央防御 | F27: 改名 | G27: 动物拟人 | K27: 卡通渲染 | L27: Tap4fun | M27: 尼毕鲁
A28: 27 | B28: Ape Warforts | C28: Ape Warforts | D28: 68b790d97804e2faa545b1a2 | E28: Ape Warforts 猿人战争堡垒 | G28: 动物拟人 | K28: 卡通渲染 | L28: Tap4Fun | M28: 尼毕鲁
A29: 28 | B29: Apex Girl | C29: Apex Girl | D29: 672b2077e986df6c4b8472f7 | E29: Apex Girl 顶级女孩 | G29: 工业/商业模拟 | H29: 美女养成 | K29: 写实 | L29: Tap4Fun | M29: 尼毕鲁
A30: 29 | B30: Apocalypse: New Dawn | C30: Apocalypse: New Dawn | D30: 68d8a63e7af55e79036a9f7b | E30: Apocalypse: New Dawn 末日：新黎明 | G30: 荒漠/沙漠/末日废土 | H30: 美女养成 | K30: 写实 | L30: XFire Games
A31: 30 | B31: Arcane Clash：Frost War | C31: Arcane Clash：Frost War | D31: 67b339a827e2c11420534e0e | E31: Arcane Clash：Frost War 神秘对决：冰封战争 | G31: 魔幻/神话/吸血鬼/幻想世界 | H31: 美女养成 | K31: 卡通渲染 | L31: xh&puzzle | M31: 三七互娱
A32: 31 | B32: Ark of War: Aim for the cosmos | C32: Ark of War: Aim for the cosmos | D32: 56cb9e3409428bf93f00015e | E32: Ark of War: Aim for the cosmos 星际海盗：星海舰队 | G32: 太空科幻 | H32: 美女养成 | K32: 写实 | L32: Seven Pirates | M32: Seven Pirates
A33: 32 | B33: Armada: Warship Legends | C33: #N/A | D33: #N/A | E33: Armada: Warships Legends 无敌舰队 | F33: 改名 | G33: 现代战争 | H33: 美女养成 | K33: 写实 | L33: TikoFun Games | M33: TikoFun
A34: 33 | B34: Armada: Warships Legends | C34: Armada: Warships Legends | D34: 6393103c42019c61acf94d10 | E34: Armada: Warships Legends 无敌舰队 | G34: 现代战争 | H34: 美女养成 | K34: 写实 | L34: TikoFun Games | M34: TikoFun
A35: 34 | B35: Art of Conquest : Airships | C35: Art of Conquest : Airships | D35: 5ba2792140ef3c2484aeedd7 | E35: Art of Conquest : Airships 剑与家园：飞空艇时代 | G35: 魔幻/神话/吸血鬼/幻想世界 | H35: 即使战略/红警 | K35: 卡通渲染 | L35: Lilith Games | M35: 莉莉丝
A36: 35 | B36: Art of War 3:RTS strategy game | C36: Art of War 3:RTS strategy game | D36: 573dcece82c356585e0006f5 | E36: Art of War 3:RTS strategy game 全球冲突 | G36: 现代战争 | H36: 即使战略/红警 | K36: 写实 | L36: 37 Interactive Entertainment | M36: 三七互娱
A37: 36 | B37: Asefat Al-Harb | C37: Asefat Al-Harb | D37: 5e20e5114de76e3e8b9e07dc | E37: Asefat Al-Harb 战争风暴 | G37: 现代战争 | K37: 写实 | L37: Stillfront Group | M37: Stillfront Group
A38: 37 | B38: Avatar: Realms Collide | C38: Avatar: Realms Collide | D38: 66698f4fb3ae27fc1429e36b | E38: Avatar: Realms Collide 降世神通 | G38: 魔幻/神话/吸血鬼/幻想世界 | H38: IP展示/蹭IP | K38: 二次元 | L38: Tilting Point | M38: Tilting Point
A39: 38 | B39: Battle Kiss:Girl's Survival | C39: Battle Kiss:Girl's Survival | D39: 685de571e53934433ee61da4 | E39: Battle Kiss:Girl's Survival 战斗之吻 | G39: 丧尸 | H39: 美女养成 | I39: 数字门/跑酷 | K39: 二次元 | L39: Smart Fun | M39: 天龙互娱
A40: 39 | B40: Battle Warship: Naval Empire | C40: Battle Warship: Naval Empire | D40: 58b61f3ad9c900778700ba11 | E40: Battle Warship: Naval Empire 战舰：海军帝国 | G40: 现代战争 | K40: 写实 | L40: Baidu | M40: Baidu
...
